Workbook

Sheet atendimentos
A1: ID | B1: DATA | C1: CLIENTE | D1: PROFISSIONAL | E1: SERVICO | F1: VALOR | G1: COMISSAO
A2: 1 | B2: 45992 | C2: CL_001 | D2: Neide Castro | E2: Design de Sobrancelha | F2: =VLOOKUP(E2, servicos!B:C, 2, 0) -> 100 | G2: =F2 * VLOOKUP(D2, profissionais!B:D, 3, 0) -> 40
A3: 2 | B3: 45992 | C3: CL_002 | D3: Mara Cristina | E3: Unhas Acrigel | F3: =VLOOKUP(E3, servicos!B:C, 2, 0) -> 280 | G3: =F3 * VLOOKUP(D3, profissionais!B:D, 3, 0) -> 112
A4: 3 | B4: 45992 | C4: CL_003 | D4: Perla Moura | E4: Box Braids | F4: =VLOOKUP(E4, servicos!B:C, 2, 0) -> 450 | G4: =F4 * VLOOKUP(D4, profissionais!B:D, 3, 0) -> 180
A5: 4 | B5: 45992 | C5: CL_004 | D5: Neide Castro | E5: Henna | F5: =VLOOKUP(E5, servicos!B:C, 2, 0) -> 45 | G5: =F5 * VLOOKUP(D5, profissionais!B:D, 3, 0) -> 18
A6: 5 | B6: 45992 | C6: CL_005 | D6: Neide Castro | E6: Design de Sobrancelha | F6: =VLOOKUP(E6, servicos!B:C, 2, 0) -> 100 | G6: =F6 * VLOOKUP(D6, profissionais!B:D, 3, 0) -> 40
A7: 6 | B7: 45992 | C7: CL_006 | D7: Zete Souza | E7: Dreads | F7: =VLOOKUP(E7, servicos!B:C, 2, 0) -> 580 | G7: =F7 * VLOOKUP(D7, profissionais!B:D, 3, 0) -> 232
A8: 7 | B8: 45992 | C8: CL_007 | D8: Mara Cristina | E8: Penteado Artistico | F8: =VLOOKUP(E8, servicos!B:C, 2, 0) -> 350 | G8: =F8 * VLOOKUP(D8, profissionais!B:D, 3, 0) -> 140
A9: 8 | B9: 45992 | C9: CL_008 | D9: Neide Castro | E9: Pé e Mão | F9: =VLOOKUP(E9, servicos!B:C, 2, 0) -> 60 | G9: =F9 * VLOOKUP(D9, profissionais!B:D, 3, 0) -> 24
A10: 9 | B10: 45993 | C10: CL_009 | D10: Jhennifer Novaes | E10: Relaxamento | F10: =VLOOKUP(E10, servicos!B:C, 2, 0) -> 150 | G10: =F10 * VLOOKUP(D10, profissionais!B:D, 3, 0) -> 60
A11: 10 | B11: 45993 | C11: CL_010 | D11: Mara Cristina | E11: Unhas Acrigel | F11: =VLOOKUP(E11, servicos!B:C, 2, 0) -> 280 | G11: =F11 * VLOOKUP(D11, profissionais!B:D, 3, 0) -> 112
A12: 11 | B12: 45993 | C12: CL_011 | D12: Perla Moura | E12: Trança Nagô | F12: =VLOOKUP(E12, servicos!B:C, 2, 0) -> 280 | G12: =F12 * VLOOKUP(D12, profissionais!B:D, 3, 0) -> 112
A13: 12 | B13: 45993 | C13: CL_012 | D13: Neide Castro | E13: Design de Sobrancelha | F13: =VLOOKUP(E13, servicos!B:C, 2, 0) -> 100 | G13: =F13 * VLOOKUP(D13, profissionais!B:D, 3, 0) -> 40
... A28: 27 | B28: 45994 | C28: CL_027 | D28: Ana Amorim | E28: Corte | F28: =VLOOKUP(E28, servicos!B:C, 2, 0) -> 150 | G28: =F28 * VLOOKUP(D28, profissionais!B:D, 3, 0) -> 60
A29: 28 | B29: 45994 | C29: CL_028 | D29: Ana Amorim | E29: Tratamento Simples | F29: =VLOOKUP(E29, servicos!B:C, 2, 0) -> 80 | G29: =IFERROR(F29 * VLOOKUP(D29, profissionais!B:D, 3, 0),"") -> 32
C30: CL_029 | D30: Perla Moura | E30: Box Braids | F30: =IFERROR(VLOOKUP(E30, servicos!B:C, 2, 0),"") -> 450 | G30: =IFERROR(F30 * VLOOKUP(D30, profissionais!B:D, 3, 0),"") -> 180
C31: CL_030 | D31: Mara Cristina | F31: =IFERROR(VLOOKUP(E31, servicos!B:C, 2, 0),"") | G31: =IFERROR(F31 * VLOOKUP(D31, profissionais!B:D, 3, 0),"") -> 0
C32: CL_031 | F32: =IFERROR(VLOOKUP(E32, servicos!B:C, 2, 0),"") | G32: =IFERROR(F32 * VLOOKUP(D32, profissionais!B:D, 3, 0),"")
C33: CL_032 | F33: =IFERROR(VLOOKUP(E33, servicos!B:C, 2, 0),"") | G33: =IFERROR(F33 * VLOOKUP(D33, profissionais!B:D, 3, 0),"")
C34: CL_033 | F34: =IFERROR(VLOOKUP(E34, servicos!B:C, 2, 0),"") | G34: =IFERROR(F34 * VLOOKUP(D34, profissionais!B:D, 3, 0),"")
C35: CL_034 | F35: =IFERROR(VLOOKUP(E35, servicos!B:C, 2, 0),"") | G35: =IFERROR(F35 * VLOOKUP(D35, profissionais!B:D, 3, 0),"")
C36: CL_035 | F36: =IFERROR(VLOOKUP(E36, servicos!B:C, 2, 0),"") | G36: =IFERROR(F36 * VLOOKUP(D36, profissionais!B:D, 3, 0),"")
C37: CL_036 | F37: =IFERROR(VLOOKUP(E37, servicos!B:C, 2, 0),"") | G37: =IFERROR(F37 * VLOOKUP(D37, profissionais!B:D, 3, 0),"")
C38: CL_037 | F38: =IFERROR(VLOOKUP(E38, servicos!B:C, 2, 0),"") | G38: =IFERROR(F38 * VLOOKUP(D38, profissionais!B:D, 3, 0),"")
C39: CL_038 | F39: =IFERROR(VLOOKUP(E39, servicos!B:C, 2, 0),"") | G39: =IFERROR(F39 * VLOOKUP(D39, profissionais!B:D, 3, 0),"")
C40: CL_039 | F40: =IFERROR(VLOOKUP(E40, servicos!B:C, 2, 0),"") | G40: =IFERROR(F40 * VLOOKUP(D40, profissionais!B:D, 3, 0),"")
C41: CL_040 | F41: =IFERROR(VLOOKUP(E41, servicos!B:C, 2, 0),"") | G41: =IFERROR(F41 * VLOOKUP(D41, profissionais!B:D, 3, 0),"")
C42: CL_041 | F42: =IFERROR(VLOOKUP(E42, servicos!B:C, 2, 0),"") | G42: =IFERROR(F42 * VLOOKUP(D42, profissionais!B:D, 3, 0),"")
C43: CL_042 | F43: =IFERROR(VLOOKUP(E43, servicos!B:C, 2, 0),"") | G43: =IFERROR(F43 * VLOOKUP(D43, profissionais!B:D, 3, 0),"")
... C45: CL_044 | F45: =IFERROR(VLOOKUP(E45, servicos!B:C, 2, 0),"") | G45: =IFERROR(F45 * VLOOKUP(D45, profissionais!B:D, 3, 0),"")
F46: =IFERROR(VLOOKUP(E46, servicos!B:C, 2, 0),"") | G46: =IFERROR(F46 * VLOOKUP(D46, profissionais!B:D, 3, 0),"")
F47: =IFERROR(VLOOKUP(E47, servicos!B:C, 2, 0),"") | G47: =IFERROR(F47 * VLOOKUP(D47, profissionais!B:D, 3, 0),"")
F48: =IFERROR(VLOOKUP(E48, servicos!B:C, 2, 0),"") | G48: =IFERROR(F48 * VLOOKUP(D48, profissionais!B:D, 3, 0),"")
F49: =IFERROR(VLOOKUP(E49, servicos!B:C, 2, 0),"") | G49: =IFERROR(F49 * VLOOKUP(D49, profissionais!B:D, 3, 0),"")
F50: =IFERROR(VLOOKUP(E50, servicos!B:C, 2, 0),"") | G50: =IFERROR(F50 * VLOOKUP(D50, profissionais!B:D, 3, 0),"")
F51: =IFERROR(VLOOKUP(E51, servicos!B:C, 2, 0),"") | G51: =IFERROR(F51 * VLOOKUP(D51, profissionais!B:D, 3, 0),"")
F52: =IFERROR(VLOOKUP(E52, servicos!B:C, 2, 0),"") | G52: =IFERROR(F52 * VLOOKUP(D52, profissionais!B:D, 3, 0),"")
F53: =IFERROR(VLOOKUP(E53, servicos!B:C, 2, 0),"") | G53: =IFERROR(F53 * VLOOKUP(D53, profissionais!B:D, 3, 0),"")
F54: =IFERROR(VLOOKUP(E54, servicos!B:C, 2, 0),"") | G54: =IFERROR(F54 * VLOOKUP(D54, profissionais!B:D, 3, 0),"")
F55: =IFERROR(VLOOKUP(E55, servicos!B:C, 2, 0),"") | G55: =IFERROR(F55 * VLOOKUP(D55, profissionais!B:D, 3, 0),"")
...

Sheet profissionais
A1: ID | B1: PROFISSIONAL | C1: ESPECIALIDADE | D1: % COMISSAO | E1: FATURAMENTO | F1: SALÁRIO TOTAL
B2: Rita Neves | C2: Pé e Mão, Unhas Acrigel | D2: 0.4 | E2: =SUMIF(atendimentos!D:D, B2, atendimentos!F:F) -> 740 | F2: =E2 * D2 -> 296
B3: Perla Moura | C3: Box Braids, Dreads, Trança Nago | D3: 0.4 | E3: =SUMIF(atendimentos!D:D, B3, atendimentos!F:F) -> 1910 | F3: =E3 * D3 -> 764
B4: Ana Amorim | C4: Corte, Tratamento Luxo, Tratamento Simples, Pé e Mão | D4: 0.4 | E4: =SUMIF(atendimentos!D:D, B4, atendimentos!F:F) -> 610 | F4: =E4 * D4 -> 244
B5: Zete Souza | C5: Box Braids, Dreads, Trança Nago | D5: 0.4 | E5: =SUMIF(atendimentos!D:D, B5, atendimentos!F:F) -> 580 | F5: =E5 * D5 -> 232
B6: Jhennifer Novaes | C6: Faux Locs, Relaxamento, Tratamento Luxo | D6: 0.4 | E6: =SUMIF(atendimentos!D:D, B6, atendimentos!F:F) -> 300 | F6: =E6 * D6 -> 120
B7: Neide Castro | C7: Design de Sobrancelha, Henna | D7: 0.4 | E7: =SUMIF(atendimentos!D:D, B7, atendimentos!F:F) -> 450 | F7: =E7 * D7 -> 180
B8: Mara Cristina | C8: Penteado Artistico, Unhas Acrigel | D8: 0.4 | E8: =SUMIF(atendimentos!D:D, B8, atendimentos!F:F) -> 1540 | F8: =E8 * D8 -> 616

Sheet servicos
A1: ID | B1: SERVICO | C1: PRECO | D1: TEMPO MEDIO
A2: 1 | B2: Pé e Mão | C2: 60 | D2: 100
A3: 2 | B3: Unhas Acrigel | C3: 280 | D3: 200
A4: 3 | B4: Box Braids | C4: 450 | D4: 500
A5: 4 | B5: Dreads | C5: 580 | D5: 500
A6: 5 | B6: Trança Nagô | C6: 280 | D6: 100
A7: 6 | B7: Corte | C7: 150 | D7: 100
A8: 7 | B8: Tratamento Luxo | C8: 150 | D8: 100
A9: 8 | B9: Tratamento Simples | C9: 80 | D9: 30
A10: 9 | B10: Faux Locs | C10: 580 | D10: 500
A11: 10 | B11: Relaxamento | C11: 150 | D11: 200
A12: 11 | B12: Design de Sobrancelha | C12: 100 | D12: 30
A13: 12 | B13: Henna | C13: 45 | D13: 30
A14: 13 | B14: Penteado Artistico | C14: 350 | D14: 200

Sheet estoque
A1: ID | B1: PRODUTO | C1: PRECO DE CUSTO | D1: PRECO DE VENDA | E1: ESTOQUE MINIMO | F1: QTD. VENDIDA | G1: ESTOQUE ATUAL
A2: 1 | B2: kit cabelo | C2: 40 | D2: 150 | E2: 10 | F2: =SUMIF(vendas!B:B, B2, vendas!C:C) -> 2 | G2: =E2 - F2 -> 8
A3: 2 | B3: oléo de coco | C3: 8 | D3: 20 | E3: 10 | F3: =SUMIF(vendas!B:B, B3, vendas!C:C) -> 4 | G3: =E3 - F3 -> 6
A4: 3 | B4: touca de cetim | C4: 3.5 | D4: 25 | E4: 10 | F4: =SUMIF(vendas!B:B, B4, vendas!C:C) -> 2 | G4: =E4 - F4 -> 8
A5: 4 | B5: durag | C5: 4.5 | D5: 35 | E5: 10 | F5: =SUMIF(vendas!B:B, B5, vendas!C:C) -> 1 | G5: =E5 - F5 -> 9
A6: 5 | B6: shampoo rei dos cachos | C6: 12 | D6: 30 | E6: 10 | F6: =SUMIF(vendas!B:B, B6, vendas!C:C) -> 2 | G6: =E6 - F6 -> 8
A7: 6 | B7: oleo extraordinario | C7: 25 | D7: 90 | E7: 10 | F7: =SUMIF(vendas!B:B, B7, vendas!C:C) -> 0 | G7: =E7 - F7 -> 10
A8: 7 | B8: merchan camisa | C8: 25 | D8: 80 | E8: 10 | F8: =SUMIF(vendas!B:B, B8, vendas!C:C) -> 2 | G8: =E8 - F8 -> 8
A9: 8 | B9: merchan ecobag | C9: 5 | D9: 25 | E9: 10 | F9: =SUMIF(vendas!B:B, B9, vendas!C:C) -> 1 | G9: =E9 - F9 -> 9
A10: 9 | B10: creme para fibra organica | C10: 7.5 | D10: 35 | E10: 10 | F10: =SUMIF(vendas!B:B, B10, vendas!C:C) -> 1 | G10: =E10 - F10 -> 9

Sheet vendas
A1: ID | B1: PRODUTO | C1: QTD. | D1: TOTAL
B2: kit cabelo | C2: 1 | D2: =IFERROR(VLOOKUP(B2, estoque!B:D, 3, 0) * C2, "") -> 150
B3: oléo de coco | C3: 2 | D3: =IFERROR(VLOOKUP(B3, estoque!B:D, 3, 0) * C3, "") -> 40
B4: merchan ecobag | C4: 1 | D4: =IFERROR(VLOOKUP(B4, estoque!B:D, 3, 0) * C4, "") -> 25
B5: shampoo rei dos cachos | C5: 1 | D5: =IFERROR(VLOOKUP(B5, estoque!B:D, 3, 0) * C5, "") -> 30
B6: durag | C6: 1 | D6: =IFERROR(VLOOKUP(B6, estoque!B:D, 3, 0) * C6, "") -> 35
B7: touca de cetim | C7: 2 | D7: =IFERROR(VLOOKUP(B7, estoque!B:D, 3, 0) * C7, "") -> 50
B8: merchan camisa | C8: 1 | D8: =IFERROR(VLOOKUP(B8, estoque!B:D, 3, 0) * C8, "") -> 80
B9: shampoo rei dos cachos | C9: 1 | D9: =IFERROR(VLOOKUP(B9, estoque!B:D, 3, 0) * C9, "") -> 30
B10: kit cabelo | C10: 1 | D10: =IFERROR(VLOOKUP(B10, estoque!B:D, 3, 0) * C10, "") -> 150
B11: oléo de coco | C11: 2 | D11: =IFERROR(VLOOKUP(B11, estoque!B:D, 3, 0) * C11, "") -> 40
B12: creme para fibra organica | C12: 1 | D12: =IFERROR(VLOOKUP(B12, estoque!B:D, 3, 0) * C12, "") -> 35
B13: merchan camisa | C13: 1 | D13: =IFERROR(VLOOKUP(B13, estoque!B:D, 3, 0) * C13, "") -> 80
D14: =IFERROR(VLOOKUP(B14, estoque!B:D, 3, 0) * C14, "")
D15: =IFERROR(VLOOKUP(B15, estoque!B:D, 3, 0) * C15, "")
D16: =IFERROR(VLOOKUP(B16, estoque!B:D, 3, 0) * C16, "")
D17: =IFERROR(VLOOKUP(B17, estoque!B:D, 3, 0) * C17, "")
D18: =IFERROR(VLOOKUP(B18, estoque!B:D, 3, 0) * C18, "")
D19: =IFERROR(VLOOKUP(B19, estoque!B:D, 3, 0) * C19, "")
D20: =IFERROR(VLOOKUP(B20, estoque!B:D, 3, 0) * C20, "")
D21: =IFERROR(VLOOKUP(B21, estoque!B:D, 3, 0) * C21, "")
D22: =IFERROR(VLOOKUP(B22, estoque!B:D, 3, 0) * C22, "")
D23: =IFERROR(VLOOKUP(B23, estoque!B:D, 3, 0) * C23, "")
D24: =IFERROR(VLOOKUP(B24, estoque!B:D, 3, 0) * C24, "")
D25: =IFERROR(VLOOKUP(B25, estoque!B:D, 3, 0) * C25, "")
... D619: =IFERROR(VLOOKUP(B619, estoque!B:D, 3, 0) * C619, "")

Sheet gastos
A1: DATA | B1: DESCRICAO | C1: CATEGORIA | D1: VALOR
C2: aluguel | D2: 1500
C3: conta de luz | D3: 500
C4: conta de internet | D4: 250
C5: material salão | D5: 800
C6: produtos de limpeza | D6: 250
C7: produtos de cozinha | D7: 250
C8: profissional de marketing | D8: 1000
C9: profissional de limpeza | D9: 1500

Sheet calculos
A1: Descrição | B1: Valor Total
A2: Total de atendimentos | B2: =SUM(atendimentos!F:F) -> 6130
A3: Total de Vendas | B3: =SUM(vendas!D:D) -> 745
A4: Faturamento Total | B4: =B2 + B3 -> 6875
A5: Total de Comissões | B5: =SUM(atendimentos!G:G) -> 2452
A6: Total de Gastos | B6: =SUM(gastos!D:D) -> 6050
A7: Lucro Liquido | B7: =B4 - B5 - B6 -> -1627
